Workbook

Sheet 集計結果
A1: Jurisdiction | B1: Department | C1: Process ID | D1: Process Name | E1: Status | F1: Total Expected Timesavings | G1: AR | H1: UR | I1: Business Cycle | J1: 90Days | K1: 30Days | L1: 7Days | M1: START | N1: COMPLETE | O1: SuccessRate | P1: 実行サイクル 判定 | Q1: 成功率判定

Sheet 実行サイクル確認
A1: Jurisdiction | B1: Department | C1: Process ID | D1: Process Name | E1: Status | F1: Total Expected Timesavings | G1: AR | H1: UR | I1: Business Cycle | J1: 90Days | K1: 30Days | L1: 7Days | M1: FLAG1 | N1: 報告者 / Reporter | O1: 原因カテゴリー （自動選択） | P1: 原因カテゴリー | Q1: 先週の対策 | R1: CR・障害対応状況 | S1: 対策カテゴリー / Action | T1: 改善予定日
O2: =IF(ISERROR(VLOOKUP(LEFT(P2,1),Master!$B$2:$C$4,2,FALSE)),"",VLOOKUP(LEFT(P2,1),Master!$B$2:$C$4,2,FALSE))
O3: =IF(ISERROR(VLOOKUP(LEFT(P3,1),Master!$B$2:$C$4,2,FALSE)),"",VLOOKUP(LEFT(P3,1),Master!$B$2:$C$4,2,FALSE))
O4: =IF(ISERROR(VLOOKUP(LEFT(P4,1),Master!$B$2:$C$4,2,FALSE)),"",VLOOKUP(LEFT(P4,1),Master!$B$2:$C$4,2,FALSE))
O5: =IF(ISERROR(VLOOKUP(LEFT(P5,1),Master!$B$2:$C$4,2,FALSE)),"",VLOOKUP(LEFT(P5,1),Master!$B$2:$C$4,2,FALSE))
O6: =IF(ISERROR(VLOOKUP(LEFT(P6,1),Master!$B$2:$C$4,2,FALSE)),"",VLOOKUP(LEFT(P6,1),Master!$B$2:$C$4,2,FALSE))
O7: =IF(ISERROR(VLOOKUP(LEFT(P7,1),Master!$B$2:$C$4,2,FALSE)),"",VLOOKUP(LEFT(P7,1),Master!$B$2:$C$4,2,FALSE))
O8: =IF(ISERROR(VLOOKUP(LEFT(P8,1),Master!$B$2:$C$4,2,FALSE)),"",VLOOKUP(LEFT(P8,1),Master!$B$2:$C$4,2,FALSE))
O9: =IF(ISERROR(VLOOKUP(LEFT(P9,1),Master!$B$2:$C$4,2,FALSE)),"",VLOOKUP(LEFT(P9,1),Master!$B$2:$C$4,2,FALSE))
O10: =IF(ISERROR(VLOOKUP(LEFT(P10,1),Master!$B$2:$C$4,2,FALSE)),"",VLOOKUP(LEFT(P10,1),Master!$B$2:$C$4,2,FALSE))
O11: =IF(ISERROR(VLOOKUP(LEFT(P11,1),Master!$B$2:$C$4,2,FALSE)),"",VLOOKUP(LEFT(P11,1),Master!$B$2:$C$4,2,FALSE))
O12: =IF(ISERROR(VLOOKUP(LEFT(P12,1),Master!$B$2:$C$4,2,FALSE)),"",VLOOKUP(LEFT(P12,1),Master!$B$2:$C$4,2,FALSE))
O13: =IF(ISERROR(VLOOKUP(LEFT(P13,1),Master!$B$2:$C$4,2,FALSE)),"",VLOOKUP(LEFT(P13,1),Master!$B$2:$C$4,2,FALSE))
... O112: =IF(ISERROR(VLOOKUP(LEFT(P112,1),Master!$B$2:$C$4,2,FALSE)),"",VLOOKUP(LEFT(P112,1),Master!$B$2:$C$4,2,FALSE))

Sheet 成功率確認
A1: Jurisdiction | B1: Department | C1: Process ID | D1: Process Name | E1: Status | F1: Total Expected Timesavings | G1: AR | H1: UR | I1: Business Cycle | J1: START | K1: COMPLETE | L1: SuccessRate | M1: FLAG2 | N1: 報告者 / Reporter | O1: カテゴリー(自動選択） | P1: 稼働率が低い原因 / Cause | Q1: 対策 / Action | R1: 対策カテゴリー | S1: 先週の対策/ActionLastWeek | T1: CR・障害対応状況 | U1: Link | V1: Kibana へのリンク | W1: カスタマイズ 閾値フラグ | X1: カスタマイズ 閾値 | Y1: カスタマイズ 閾値設定理由
U2: =Master!$R$2 &C2&Master!$R$3 -> https://rpa-dashboard.fastretailing.com/_plugin/kibana/app/kibana?security_tenant=global#/dashboard/77b46580-9bf7-11ea-a8b6-e9141704cca0?_g=(refreshInterval:(pause:!t,value:0),time:(from:'2020-10-04T15:00:00.000Z',mode:quick,to:'2020-10-11T14:59:59.999Z'))&_a=(description:'',filters:!(),fullScreenMode:!f,options:(darkTheme:!f,hidePanelTitles:!f,useMargins:!t),panels:!((embeddableConfig:(),gridData:(h:10,i:'3',w:17,x:31,y:20),id:e74898b0-61de-11ea-95af-917550a0bc8f,panelIndex:'3',type:visualization,version:'6.4.2'),(embeddableConfig:(),gridData:(h:10,i:'6',w:31,x:0,y:30),id:'8a0f3b00-6750-11ea-95af-917550a0bc8f',panelIndex:'6',type:visualization,version:'6.4.2'),(embeddableConfig:(),gridData:(h:10,i:'7',w:16,x:31,y:30),id:b10c4c00-6cf2-11ea-95af-917550a0bc8f,panelIndex:'7',type:visualization,version:'6.4.2'),(embeddableConfig:(),gridData:(h:10,i:'10',w:17,x:31,y:10),id:'8cae0c40-6cf7-11ea-95af-917550a0bc8f',panelIndex:'10',type:visualization,version:'6.4.2'),(embeddableConfig:(),gridData:(h:10,i:'12',w:16,x:31,y:40),id:'73b8e800-d601-11e9-a222-8b80233e6888',panelIndex:'12',type:visualization,version:'6.4.2'),(embeddableConfig:(),gridData:(h:10,i:'13',w:31,x:0,y:40),id:'58e36640-d601-11e9-a222-8b80233e6888',panelIndex:'13',type:visualization,version:'6.4.2'),(embeddableConfig:(),gridData:(h:10,i:'15',w:31,x:0,y:50),id:'578e0810-d604-11e9-a222-8b80233e6888',panelIndex:'15',type:visualization,version:'6.4.2'),(embeddableConfig:(),gridData:(h:10,i:'16',w:16,x:31,y:50),id:'88bdbca0-d604-11e9-a222-8b80233e6888',panelIndex:'16',type:visualization,version:'6.4.2'),(embeddableConfig:(),gridData:(h:9,i:'18',w:31,x:0,y:70),id:'0e4a0eb0-101a-11ea-95af-917550a0bc8f',panelIndex:'18',type:visualization,version:'6.4.2'),(embeddableConfig:(),gridData:(h:10,i:'19',w:31,x:0,y:60),id:fd252c00-1019-11ea-95af-917550a0bc8f,panelIndex:'19',type:visualization,version:'6.4.2'),(embeddableConfig:(vis:(colors:(BRO%E7%B5%82%E4%BA%86%E5%9B%9E%E6%95%B0:%23629E51,BRO%E9%96%8B%E5%A7%8B%E5%9B%9E%E6%95%B0:%23447EBC,'COM_TYPE:%22EXC%22+AND+COM_STATUS:%22START%22':%23629E51,EXCEL%E7%B5%82%E4%BA%86%E5%9B%9E%E6%95%B0:%23629E51,EXCEL%E9%96%8B%E5%A7%8B%E5%9B%9E%E6%95%B0:%2364B0C8),legendOpen:!t)),gridData:(h:8,i:'21',w:31,x:0,y:79),id:'42fb81e0-6f4f-11ea-95af-917550a0bc8f',panelIndex:'21',type:visualization,version:'6.4.2'),(embeddableConfig:(),gridData:(h:10,i:'22',w:31,x:0,y:87),id:'51f79120-6f4f-11ea-95af-917550a0bc8f',panelIndex:'22',type:visualization,version:'6.4.2'),(embeddableConfig:(),gridData:(h:18,i:'23',w:17,x:31,y:79),id:'6b8a80c0-6f4f-11ea-95af-917550a0bc8f',panelIndex:'23',type:visualization,version:'6.4.2'),(embeddableConfig:(),gridData:(h:10,i:'24',w:31,x:0,y:97),id:'707ecfc0-72fe-11ea-95af-917550a0bc8f',panelIndex:'24',type:visualization,version:'6.4.2'),(embeddableConfig:(),gridData:(h:11,i:'25',w:31,x:0,y:107),id:'838d32f0-72fe-11ea-95af-917550a0bc8f',panelIndex:'25',type:visualization,version:'6.4.2'),(embeddableConfig:(),gridData:(h:21,i:'26',w:17,x:31,y:97),id:a7ed2e20-72fe-11ea-95af-917550a0bc8f,panelIndex:'26',type:visualization,version:'6.4.2'),(embeddableConfig:(),gridData:(h:10,i:'29',w:31,x:0,y:0),id:a0e60ef0-7324-11ea-95af-917550a0bc8f,panelIndex:'29',type:visualization,version:'6.4.2'),(embeddableConfig:(),gridData:(h:10,i:'30',w:17,x:31,y:0),id:cf110f00-7324-11ea-95af-917550a0bc8f,panelIndex:'30',type:visualization,version:'6.4.2'),(embeddableConfig:(),gridData:(h:10,i:'31',w:31,x:0,y:10),id:'0e7707e0-7a22-11ea-b987-ab21273de917',panelIndex:'31',type:visualization,version:'6.4.2'),(embeddableConfig:(),gridData:(h:19,i:'32',w:17,x:31,y:60),id:'82ba1a60-7a23-11ea-b27e-a53d919190b3',panelIndex:'32',type:visualization,version:'6.4.2'),(embeddableConfig:(),gridData:(h:23,i:'33',w:48,x:0,y:118),id:c372aca0-ba94-11ea-a8b6-e9141704cca0,panelIndex:'33',type:visualization,version:'6.8.0'),(embeddableConfig:(),gridData:(h:10,i:'34',w:31,x:0,y:20),id:'625e8670-c640-11ea-af3e-fb03f75ac9e6',panelIndex:'34',type:visualization,version:'6.8.0'),(embeddableConfig:(),gridData:(h:24,i:'35',w:48,x:0,y:141),id:'7ea8a0b0-d6b0-11ea-9d09-eb7b980d6b7e',panelIndex:'35',type:search,version:'6.8.0')),query:(language:lucene,query:'processName:*'),timeRestore:!f,title:das_Common_Process_detail,viewMode:view) | V2: =HYPERLINK(U2, "link") -> #VALUE!
U3: =Master!$R$2 &C3&Master!$R$3 -> https://rpa-dashboard.fastretailing.com/_plugin/kibana/app/kibana?security_tenant=global#/dashboard/77b46580-9bf7-11ea-a8b6-e9141704cca0?_g=(refreshInterval:(pause:!t,value:0),time:(from:'2020-10-04T15:00:00.000Z',mode:quick,to:'2020-10-11T14:59:59.999Z'))&_a=(description:'',filters:!(),fullScreenMode:!f,options:(darkTheme:!f,hidePanelTitles:!f,useMargins:!t),panels:!((embeddableConfig:(),gridData:(h:10,i:'3',w:17,x:31,y:20),id:e74898b0-61de-11ea-95af-917550a0bc8f,panelIndex:'3',type:visualization,version:'6.4.2'),(embeddableConfig:(),gridData:(h:10,i:'6',w:31,x:0,y:30),id:'8a0f3b00-6750-11ea-95af-917550a0bc8f',panelIndex:'6',type:visualization,version:'6.4.2'),(embeddableConfig:(),gridData:(h:10,i:'7',w:16,x:31,y:30),id:b10c4c00-6cf2-11ea-95af-917550a0bc8f,panelIndex:'7',type:visualization,version:'6.4.2'),(embeddableConfig:(),gridData:(h:10,i:'10',w:17,x:31,y:10),id:'8cae0c40-6cf7-11ea-95af-917550a0bc8f',panelIndex:'10',type:visualization,version:'6.4.2'),(embeddableConfig:(),gridData:(h:10,i:'12',w:16,x:31,y:40),id:'73b8e800-d601-11e9-a222-8b80233e6888',panelIndex:'12',type:visualization,version:'6.4.2'),(embeddableConfig:(),gridData:(h:10,i:'13',w:31,x:0,y:40),id:'58e36640-d601-11e9-a222-8b80233e6888',panelIndex:'13',type:visualization,version:'6.4.2'),(embeddableConfig:(),gridData:(h:10,i:'15',w:31,x:0,y:50),id:'578e0810-d604-11e9-a222-8b80233e6888',panelIndex:'15',type:visualization,version:'6.4.2'),(embeddableConfig:(),gridData:(h:10,i:'16',w:16,x:31,y:50),id:'88bdbca0-d604-11e9-a222-8b80233e6888',panelIndex:'16',type:visualization,version:'6.4.2'),(embeddableConfig:(),gridData:(h:9,i:'18',w:31,x:0,y:70),id:'0e4a0eb0-101a-11ea-95af-917550a0bc8f',panelIndex:'18',type:visualization,version:'6.4.2'),(embeddableConfig:(),gridData:(h:10,i:'19',w:31,x:0,y:60),id:fd252c00-1019-11ea-95af-917550a0bc8f,panelIndex:'19',type:visualization,version:'6.4.2'),(embeddableConfig:(vis:(colors:(BRO%E7%B5%82%E4%BA%86%E5%9B%9E%E6%95%B0:%23629E51,BRO%E9%96%8B%E5%A7%8B%E5%9B%9E%E6%95%B0:%23447EBC,'COM_TYPE:%22EXC%22+AND+COM_STATUS:%22START%22':%23629E51,EXCEL%E7%B5%82%E4%BA%86%E5%9B%9E%E6%95%B0:%23629E51,EXCEL%E9%96%8B%E5%A7%8B%E5%9B%9E%E6%95%B0:%2364B0C8),legendOpen:!t)),gridData:(h:8,i:'21',w:31,x:0,y:79),id:'42fb81e0-6f4f-11ea-95af-917550a0bc8f',panelIndex:'21',type:visualization,version:'6.4.2'),(embeddableConfig:(),gridData:(h:10,i:'22',w:31,x:0,y:87),id:'51f79120-6f4f-11ea-95af-917550a0bc8f',panelIndex:'22',type:visualization,version:'6.4.2'),(embeddableConfig:(),gridData:(h:18,i:'23',w:17,x:31,y:79),id:'6b8a80c0-6f4f-11ea-95af-917550a0bc8f',panelIndex:'23',type:visualization,version:'6.4.2'),(embeddableConfig:(),gridData:(h:10,i:'24',w:31,x:0,y:97),id:'707ecfc0-72fe-11ea-95af-917550a0bc8f',panelIndex:'24',type:visualization,version:'6.4.2'),(embeddableConfig:(),gridData:(h:11,i:'25',w:31,x:0,y:107),id:'838d32f0-72fe-11ea-95af-917550a0bc8f',panelIndex:'25',type:visualization,version:'6.4.2'),(embeddableConfig:(),gridData:(h:21,i:'26',w:17,x:31,y:97),id:a7ed2e20-72fe-11ea-95af-917550a0bc8f,panelIndex:'26',type:visualization,version:'6.4.2'),(embeddableConfig:(),gridData:(h:10,i:'29',w:31,x:0,y:0),id:a0e60ef0-7324-11ea-95af-917550a0bc8f,panelIndex:'29',type:visualization,version:'6.4.2'),(embeddableConfig:(),gridData:(h:10,i:'30',w:17,x:31,y:0),id:cf110f00-7324-11ea-95af-917550a0bc8f,panelIndex:'30',type:visualization,version:'6.4.2'),(embeddableConfig:(),gridData:(h:10,i:'31',w:31,x:0,y:10),id:'0e7707e0-7a22-11ea-b987-ab21273de917',panelIndex:'31',type:visualization,version:'6.4.2'),(embeddableConfig:(),gridData:(h:19,i:'32',w:17,x:31,y:60),id:'82ba1a60-7a23-11ea-b27e-a53d919190b3',panelIndex:'32',type:visualization,version:'6.4.2'),(embeddableConfig:(),gridData:(h:23,i:'33',w:48,x:0,y:118),id:c372aca0-ba94-11ea-a8b6-e9141704cca0,panelIndex:'33',type:visualization,version:'6.8.0'),(embeddableConfig:(),gridData:(h:10,i:'34',w:31,x:0,y:20),id:'625e8670-c640-11ea-af3e-fb03f75ac9e6',panelIndex:'34',type:visualization,version:'6.8.0'),(embeddableConfig:(),gridData:(h:24,i:'35',w:48,x:0,y:141),id:'7ea8a0b0-d6b0-11ea-9d09-eb7b980d6b7e',panelIndex:'35',type:search,version:'6.8.0')),query:(language:lucene,query:'processName:*'),timeRestore:!f,title:das_Common_Process_detail,viewMode:view) | V3: =HYPERLINK(U3, "link") -> #VALUE!
U4: =Master!$R$2 &C4&Master!$R$3 -> https://rpa-dashboard.fastretailing.com/_plugin/kibana/app/kibana?security_tenant=global#/dashboard/77b46580-9bf7-11ea-a8b6-e9141704cca0?_g=(refreshInterval:(pause:!t,value:0),time:(from:'2020-10-04T15:00:00.000Z',mode:quick,to:'2020-10-11T14:59:59.999Z'))&_a=(description:'',filters:!(),fullScreenMode:!f,options:(darkTheme:!f,hidePanelTitles:!f,useMargins:!t),panels:!((embeddableConfig:(),gridData:(h:10,i:'3',w:17,x:31,y:20),id:e74898b0-61de-11ea-95af-917550a0bc8f,panelIndex:'3',type:visualization,version:'6.4.2'),(embeddableConfig:(),gridData:(h:10,i:'6',w:31,x:0,y:30),id:'8a0f3b00-6750-11ea-95af-917550a0bc8f',panelIndex:'6',type:visualization,version:'6.4.2'),(embeddableConfig:(),gridData:(h:10,i:'7',w:16,x:31,y:30),id:b10c4c00-6cf2-11ea-95af-917550a0bc8f,panelIndex:'7',type:visualization,version:'6.4.2'),(embeddableConfig:(),gridData:(h:10,i:'10',w:17,x:31,y:10),id:'8cae0c40-6cf7-11ea-95af-917550a0bc8f',panelIndex:'10',type:visualization,version:'6.4.2'),(embeddableConfig:(),gridData:(h:10,i:'12',w:16,x:31,y:40),id:'73b8e800-d601-11e9-a222-8b80233e6888',panelIndex:'12',type:visualization,version:'6.4.2'),(embeddableConfig:(),gridData:(h:10,i:'13',w:31,x:0,y:40),id:'58e36640-d601-11e9-a222-8b80233e6888',panelIndex:'13',type:visualization,version:'6.4.2'),(embeddableConfig:(),gridData:(h:10,i:'15',w:31,x:0,y:50),id:'578e0810-d604-11e9-a222-8b80233e6888',panelIndex:'15',type:visualization,version:'6.4.2'),(embeddableConfig:(),gridData:(h:10,i:'16',w:16,x:31,y:50),id:'88bdbca0-d604-11e9-a222-8b80233e6888',panelIndex:'16',type:visualization,version:'6.4.2'),(embeddableConfig:(),gridData:(h:9,i:'18',w:31,x:0,y:70),id:'0e4a0eb0-101a-11ea-95af-917550a0bc8f',panelIndex:'18',type:visualization,version:'6.4.2'),(embeddableConfig:(),gridData:(h:10,i:'19',w:31,x:0,y:60),id:fd252c00-1019-11ea-95af-917550a0bc8f,panelIndex:'19',type:visualization,version:'6.4.2'),(embeddableConfig:(vis:(colors:(BRO%E7%B5%82%E4%BA%86%E5%9B%9E%E6%95%B0:%23629E51,BRO%E9%96%8B%E5%A7%8B%E5%9B%9E%E6%95%B0:%23447EBC,'COM_TYPE:%22EXC%22+AND+COM_STATUS:%22START%22':%23629E51,EXCEL%E7%B5%82%E4%BA%86%E5%9B%9E%E6%95%B0:%23629E51,EXCEL%E9%96%8B%E5%A7%8B%E5%9B%9E%E6%95%B0:%2364B0C8),legendOpen:!t)),gridData:(h:8,i:'21',w:31,x:0,y:79),id:'42fb81e0-6f4f-11ea-95af-917550a0bc8f',panelIndex:'21',type:visualization,version:'6.4.2'),(embeddableConfig:(),gridData:(h:10,i:'22',w:31,x:0,y:87),id:'51f79120-6f4f-11ea-95af-917550a0bc8f',panelIndex:'22',type:visualization,version:'6.4.2'),(embeddableConfig:(),gridData:(h:18,i:'23',w:17,x:31,y:79),id:'6b8a80c0-6f4f-11ea-95af-917550a0bc8f',panelIndex:'23',type:visualization,version:'6.4.2'),(embeddableConfig:(),gridData:(h:10,i:'24',w:31,x:0,y:97),id:'707ecfc0-72fe-11ea-95af-917550a0bc8f',panelIndex:'24',type:visualization,version:'6.4.2'),(embeddableConfig:(),gridData:(h:11,i:'25',w:31,x:0,y:107),id:'838d32f0-72fe-11ea-95af-917550a0bc8f',panelIndex:'25',type:visualization,version:'6.4.2'),(embeddableConfig:(),gridData:(h:21,i:'26',w:17,x:31,y:97),id:a7ed2e20-72fe-11ea-95af-917550a0bc8f,panelIndex:'26',type:visualization,version:'6.4.2'),(embeddableConfig:(),gridData:(h:10,i:'29',w:31,x:0,y:0),id:a0e60ef0-7324-11ea-95af-917550a0bc8f,panelIndex:'29',type:visualization,version:'6.4.2'),(embeddableConfig:(),gridData:(h:10,i:'30',w:17,x:31,y:0),id:cf110f00-7324-11ea-95af-917550a0bc8f,panelIndex:'30',type:visualization,version:'6.4.2'),(embeddableConfig:(),gridData:(h:10,i:'31',w:31,x:0,y:10),id:'0e7707e0-7a22-11ea-b987-ab21273de917',panelIndex:'31',type:visualization,version:'6.4.2'),(embeddableConfig:(),gridData:(h:19,i:'32',w:17,x:31,y:60),id:'82ba1a60-7a23-11ea-b27e-a53d919190b3',panelIndex:'32',type:visualization,version:'6.4.2'),(embeddableConfig:(),gridData:(h:23,i:'33',w:48,x:0,y:118),id:c372aca0-ba94-11ea-a8b6-e9141704cca0,panelIndex:'33',type:visualization,version:'6.8.0'),(embeddableConfig:(),gridData:(h:10,i:'34',w:31,x:0,y:20),id:'625e8670-c640-11ea-af3e-fb03f75ac9e6',panelIndex:'34',type:visualization,version:'6.8.0'),(embeddableConfig:(),gridData:(h:24,i:'35',w:48,x:0,y:141),id:'7ea8a0b0-d6b0-11ea-9d09-eb7b980d6b7e',panelIndex:'35',type:search,version:'6.8.0')),query:(language:lucene,query:'processName:*'),timeRestore:!f,title:das_Common_Process_detail,viewMode:view) | V4: =HYPERLINK(U4, "link") -> #VALUE!
U5: =Master!$R$2 &C5&Master!$R$3 -> https://rpa-dashboard.fastretailing.com/_plugin/kibana/app/kibana?security_tenant=global#/dashboard/77b46580-9bf7-11ea-a8b6-e9141704cca0?_g=(refreshInterval:(pause:!t,value:0),time:(from:'2020-10-04T15:00:00.000Z',mode:quick,to:'2020-10-11T14:59:59.999Z'))&_a=(description:'',filters:!(),fullScreenMode:!f,options:(darkTheme:!f,hidePanelTitles:!f,useMargins:!t),panels:!((embeddableConfig:(),gridData:(h:10,i:'3',w:17,x:31,y:20),id:e74898b0-61de-11ea-95af-917550a0bc8f,panelIndex:'3',type:visualization,version:'6.4.2'),(embeddableConfig:(),gridData:(h:10,i:'6',w:31,x:0,y:30),id:'8a0f3b00-6750-11ea-95af-917550a0bc8f',panelIndex:'6',type:visualization,version:'6.4.2'),(embeddableConfig:(),gridData:(h:10,i:'7',w:16,x:31,y:30),id:b10c4c00-6cf2-11ea-95af-917550a0bc8f,panelIndex:'7',type:visualization,version:'6.4.2'),(embeddableConfig:(),gridData:(h:10,i:'10',w:17,x:31,y:10),id:'8cae0c40-6cf7-11ea-95af-917550a0bc8f',panelIndex:'10',type:visualization,version:'6.4.2'),(embeddableConfig:(),gridData:(h:10,i:'12',w:16,x:31,y:40),id:'73b8e800-d601-11e9-a222-8b80233e6888',panelIndex:'12',type:visualization,version:'6.4.2'),(embeddableConfig:(),gridData:(h:10,i:'13',w:31,x:0,y:40),id:'58e36640-d601-11e9-a222-8b80233e6888',panelIndex:'13',type:visualization,version:'6.4.2'),(embeddableConfig:(),gridData:(h:10,i:'15',w:31,x:0,y:50),id:'578e0810-d604-11e9-a222-8b80233e6888',panelIndex:'15',type:visualization,version:'6.4.2'),(embeddableConfig:(),gridData:(h:10,i:'16',w:16,x:31,y:50),id:'88bdbca0-d604-11e9-a222-8b80233e6888',panelIndex:'16',type:visualization,version:'6.4.2'),(embeddableConfig:(),gridData:(h:9,i:'18',w:31,x:0,y:70),id:'0e4a0eb0-101a-11ea-95af-917550a0bc8f',panelIndex:'18',type:visualization,version:'6.4.2'),(embeddableConfig:(),gridData:(h:10,i:'19',w:31,x:0,y:60),id:fd252c00-1019-11ea-95af-917550a0bc8f,panelIndex:'19',type:visualization,version:'6.4.2'),(embeddableConfig:(vis:(colors:(BRO%E7%B5%82%E4%BA%86%E5%9B%9E%E6%95%B0:%23629E51,BRO%E9%96%8B%E5%A7%8B%E5%9B%9E%E6%95%B0:%23447EBC,'COM_TYPE:%22EXC%22+AND+COM_STATUS:%22START%22':%23629E51,EXCEL%E7%B5%82%E4%BA%86%E5%9B%9E%E6%95%B0:%23629E51,EXCEL%E9%96%8B%E5%A7%8B%E5%9B%9E%E6%95%B0:%2364B0C8),legendOpen:!t)),gridData:(h:8,i:'21',w:31,x:0,y:79),id:'42fb81e0-6f4f-11ea-95af-917550a0bc8f',panelIndex:'21',type:visualization,version:'6.4.2'),(embeddableConfig:(),gridData:(h:10,i:'22',w:31,x:0,y:87),id:'51f79120-6f4f-11ea-95af-917550a0bc8f',panelIndex:'22',type:visualization,version:'6.4.2'),(embeddableConfig:(),gridData:(h:18,i:'23',w:17,x:31,y:79),id:'6b8a80c0-6f4f-11ea-95af-917550a0bc8f',panelIndex:'23',type:visualization,version:'6.4.2'),(embeddableConfig:(),gridData:(h:10,i:'24',w:31,x:0,y:97),id:'707ecfc0-72fe-11ea-95af-917550a0bc8f',panelIndex:'24',type:visualization,version:'6.4.2'),(embeddableConfig:(),gridData:(h:11,i:'25',w:31,x:0,y:107),id:'838d32f0-72fe-11ea-95af-917550a0bc8f',panelIndex:'25',type:visualization,version:'6.4.2'),(embeddableConfig:(),gridData:(h:21,i:'26',w:17,x:31,y:97),id:a7ed2e20-72fe-11ea-95af-917550a0bc8f,panelIndex:'26',type:visualization,version:'6.4.2'),(embeddableConfig:(),gridData:(h:10,i:'29',w:31,x:0,y:0),id:a0e60ef0-7324-11ea-95af-917550a0bc8f,panelIndex:'29',type:visualization,version:'6.4.2'),(embeddableConfig:(),gridData:(h:10,i:'30',w:17,x:31,y:0),id:cf110f00-7324-11ea-95af-917550a0bc8f,panelIndex:'30',type:visualization,version:'6.4.2'),(embeddableConfig:(),gridData:(h:10,i:'31',w:31,x:0,y:10),id:'0e7707e0-7a22-11ea-b987-ab21273de917',panelIndex:'31',type:visualization,version:'6.4.2'),(embeddableConfig:(),gridData:(h:19,i:'32',w:17,x:31,y:60),id:'82ba1a60-7a23-11ea-b27e-a53d919190b3',panelIndex:'32',type:visualization,version:'6.4.2'),(embeddableConfig:(),gridData:(h:23,i:'33',w:48,x:0,y:118),id:c372aca0-ba94-11ea-a8b6-e9141704cca0,panelIndex:'33',type:visualization,version:'6.8.0'),(embeddableConfig:(),gridData:(h:10,i:'34',w:31,x:0,y:20),id:'625e8670-c640-11ea-af3e-fb03f75ac9e6',panelIndex:'34',type:visualization,version:'6.8.0'),(embeddableConfig:(),gridData:(h:24,i:'35',w:48,x:0,y:141),id:'7ea8a0b0-d6b0-11ea-9d09-eb7b980d6b7e',panelIndex:'35',type:search,version:'6.8.0')),query:(language:lucene,query:'processName:*'),timeRestore:!f,title:das_Common_Process_detail,viewMode:view) | V5: =HYPERLINK(U5, "link") -> #VALUE!
U6: =Master!$R$2 &C6&Master!$R$3 -> https://rpa-dashboard.fastretailing.com/_plugin/kibana/app/kibana?security_tenant=global#/dashboard/77b46580-9bf7-11ea-a8b6-e9141704cca0?_g=(refreshInterval:(pause:!t,value:0),time:(from:'2020-10-04T15:00:00.000Z',mode:quick,to:'2020-10-11T14:59:59.999Z'))&_a=(description:'',filters:!(),fullScreenMode:!f,options:(darkTheme:!f,hidePanelTitles:!f,useMargins:!t),panels:!((embeddableConfig:(),gridData:(h:10,i:'3',w:17,x:31,y:20),id:e74898b0-61de-11ea-95af-917550a0bc8f,panelIndex:'3',type:visualization,version:'6.4.2'),(embeddableConfig:(),gridData:(h:10,i:'6',w:31,x:0,y:30),id:'8a0f3b00-6750-11ea-95af-917550a0bc8f',panelIndex:'6',type:visualization,version:'6.4.2'),(embeddableConfig:(),gridData:(h:10,i:'7',w:16,x:31,y:30),id:b10c4c00-6cf2-11ea-95af-917550a0bc8f,panelIndex:'7',type:visualization,version:'6.4.2'),(embeddableConfig:(),gridData:(h:10,i:'10',w:17,x:31,y:10),id:'8cae0c40-6cf7-11ea-95af-917550a0bc8f',panelIndex:'10',type:visualization,version:'6.4.2'),(embeddableConfig:(),gridData:(h:10,i:'12',w:16,x:31,y:40),id:'73b8e800-d601-11e9-a222-8b80233e6888',panelIndex:'12',type:visualization,version:'6.4.2'),(embeddableConfig:(),gridData:(h:10,i:'13',w:31,x:0,y:40),id:'58e36640-d601-11e9-a222-8b80233e6888',panelIndex:'13',type:visualization,version:'6.4.2'),(embeddableConfig:(),gridData:(h:10,i:'15',w:31,x:0,y:50),id:'578e0810-d604-11e9-a222-8b80233e6888',panelIndex:'15',type:visualization,version:'6.4.2'),(embeddableConfig:(),gridData:(h:10,i:'16',w:16,x:31,y:50),id:'88bdbca0-d604-11e9-a222-8b80233e6888',panelIndex:'16',type:visualization,version:'6.4.2'),(embeddableConfig:(),gridData:(h:9,i:'18',w:31,x:0,y:70),id:'0e4a0eb0-101a-11ea-95af-917550a0bc8f',panelIndex:'18',type:visualization,version:'6.4.2'),(embeddableConfig:(),gridData:(h:10,i:'19',w:31,x:0,y:60),id:fd252c00-1019-11ea-95af-917550a0bc8f,panelIndex:'19',type:visualization,version:'6.4.2'),(embeddableConfig:(vis:(colors:(BRO%E7%B5%82%E4%BA%86%E5%9B%9E%E6%95%B0:%23629E51,BRO%E9%96%8B%E5%A7%8B%E5%9B%9E%E6%95%B0:%23447EBC,'COM_TYPE:%22EXC%22+AND+COM_STATUS:%22START%22':%23629E51,EXCEL%E7%B5%82%E4%BA%86%E5%9B%9E%E6%95%B0:%23629E51,EXCEL%E9%96%8B%E5%A7%8B%E5%9B%9E%E6%95%B0:%2364B0C8),legendOpen:!t)),gridData:(h:8,i:'21',w:31,x:0,y:79),id:'42fb81e0-6f4f-11ea-95af-917550a0bc8f',panelIndex:'21',type:visualization,version:'6.4.2'),(embeddableConfig:(),gridData:(h:10,i:'22',w:31,x:0,y:87),id:'51f79120-6f4f-11ea-95af-917550a0bc8f',panelIndex:'22',type:visualization,version:'6.4.2'),(embeddableConfig:(),gridData:(h:18,i:'23',w:17,x:31,y:79),id:'6b8a80c0-6f4f-11ea-95af-917550a0bc8f',panelIndex:'23',type:visualization,version:'6.4.2'),(embeddableConfig:(),gridData:(h:10,i:'24',w:31,x:0,y:97),id:'707ecfc0-72fe-11ea-95af-917550a0bc8f',panelIndex:'24',type:visualization,version:'6.4.2'),(embeddableConfig:(),gridData:(h:11,i:'25',w:31,x:0,y:107),id:'838d32f0-72fe-11ea-95af-917550a0bc8f',panelIndex:'25',type:visualization,version:'6.4.2'),(embeddableConfig:(),gridData:(h:21,i:'26',w:17,x:31,y:97),id:a7ed2e20-72fe-11ea-95af-917550a0bc8f,panelIndex:'26',type:visualization,version:'6.4.2'),(embeddableConfig:(),gridData:(h:10,i:'29',w:31,x:0,y:0),id:a0e60ef0-7324-11ea-95af-917550a0bc8f,panelIndex:'29',type:visualization,version:'6.4.2'),(embeddableConfig:(),gridData:(h:10,i:'30',w:17,x:31,y:0),id:cf110f00-7324-11ea-95af-917550a0bc8f,panelIndex:'30',type:visualization,version:'6.4.2'),(embeddableConfig:(),gridData:(h:10,i:'31',w:31,x:0,y:10),id:'0e7707e0-7a22-11ea-b987-ab21273de917',panelIndex:'31',type:visualization,version:'6.4.2'),(embeddableConfig:(),gridData:(h:19,i:'32',w:17,x:31,y:60),id:'82ba1a60-7a23-11ea-b27e-a53d919190b3',panelIndex:'32',type:visualization,version:'6.4.2'),(embeddableConfig:(),gridData:(h:23,i:'33',w:48,x:0,y:118),id:c372aca0-ba94-11ea-a8b6-e9141704cca0,panelIndex:'33',type:visualization,version:'6.8.0'),(embeddableConfig:(),gridData:(h:10,i:'34',w:31,x:0,y:20),id:'625e8670-c640-11ea-af3e-fb03f75ac9e6',panelIndex:'34',type:visualization,version:'6.8.0'),(embeddableConfig:(),gridData:(h:24,i:'35',w:48,x:0,y:141),id:'7ea8a0b0-d6b0-11ea-9d09-eb7b980d6b7e',panelIndex:'35',type:search,version:'6.8.0')),query:(language:lucene,query:'processName:*'),timeRestore:!f,title:das_Common_Process_detail,viewMode:view) | V6: =HYPERLINK(U6, "link") -> #VALUE!
U7: =Master!$R$2 &C7&Master!$R$3 -> https://rpa-dashboard.fastretailing.com/_plugin/kibana/app/kibana?security_tenant=global#/dashboard/77b46580-9bf7-11ea-a8b6-e9141704cca0?_g=(refreshInterval:(pause:!t,value:0),time:(from:'2020-10-04T15:00:00.000Z',mode:quick,to:'2020-10-11T14:59:59.999Z'))&_a=(description:'',filters:!(),fullScreenMode:!f,options:(darkTheme:!f,hidePanelTitles:!f,useMargins:!t),panels:!((embeddableConfig:(),gridData:(h:10,i:'3',w:17,x:31,y:20),id:e74898b0-61de-11ea-95af-917550a0bc8f,panelIndex:'3',type:visualization,version:'6.4.2'),(embeddableConfig:(),gridData:(h:10,i:'6',w:31,x:0,y:30),id:'8a0f3b00-6750-11ea-95af-917550a0bc8f',panelIndex:'6',type:visualization,version:'6.4.2'),(embeddableConfig:(),gridData:(h:10,i:'7',w:16,x:31,y:30),id:b10c4c00-6cf2-11ea-95af-917550a0bc8f,panelIndex:'7',type:visualization,version:'6.4.2'),(embeddableConfig:(),gridData:(h:10,i:'10',w:17,x:31,y:10),id:'8cae0c40-6cf7-11ea-95af-917550a0bc8f',panelIndex:'10',type:visualization,version:'6.4.2'),(embeddableConfig:(),gridData:(h:10,i:'12',w:16,x:31,y:40),id:'73b8e800-d601-11e9-a222-8b80233e6888',panelIndex:'12',type:visualization,version:'6.4.2'),(embeddableConfig:(),gridData:(h:10,i:'13',w:31,x:0,y:40),id:'58e36640-d601-11e9-a222-8b80233e6888',panelIndex:'13',type:visualization,version:'6.4.2'),(embeddableConfig:(),gridData:(h:10,i:'15',w:31,x:0,y:50),id:'578e0810-d604-11e9-a222-8b80233e6888',panelIndex:'15',type:visualization,version:'6.4.2'),(embeddableConfig:(),gridData:(h:10,i:'16',w:16,x:31,y:50),id:'88bdbca0-d604-11e9-a222-8b80233e6888',panelIndex:'16',type:visualization,version:'6.4.2'),(embeddableConfig:(),gridData:(h:9,i:'18',w:31,x:0,y:70),id:'0e4a0eb0-101a-11ea-95af-917550a0bc8f',panelIndex:'18',type:visualization,version:'6.4.2'),(embeddableConfig:(),gridData:(h:10,i:'19',w:31,x:0,y:60),id:fd252c00-1019-11ea-95af-917550a0bc8f,panelIndex:'19',type:visualization,version:'6.4.2'),(embeddableConfig:(vis:(colors:(BRO%E7%B5%82%E4%BA%86%E5%9B%9E%E6%95%B0:%23629E51,BRO%E9%96%8B%E5%A7%8B%E5%9B%9E%E6%95%B0:%23447EBC,'COM_TYPE:%22EXC%22+AND+COM_STATUS:%22START%22':%23629E51,EXCEL%E7%B5%82%E4%BA%86%E5%9B%9E%E6%95%B0:%23629E51,EXCEL%E9%96%8B%E5%A7%8B%E5%9B%9E%E6%95%B0:%2364B0C8),legendOpen:!t)),gridData:(h:8,i:'21',w:31,x:0,y:79),id:'42fb81e0-6f4f-11ea-95af-917550a0bc8f',panelIndex:'21',type:visualization,version:'6.4.2'),(embeddableConfig:(),gridData:(h:10,i:'22',w:31,x:0,y:87),id:'51f79120-6f4f-11ea-95af-917550a0bc8f',panelIndex:'22',type:visualization,version:'6.4.2'),(embeddableConfig:(),gridData:(h:18,i:'23',w:17,x:31,y:79),id:'6b8a80c0-6f4f-11ea-95af-917550a0bc8f',panelIndex:'23',type:visualization,version:'6.4.2'),(embeddableConfig:(),gridData:(h:10,i:'24',w:31,x:0,y:97),id:'707ecfc0-72fe-11ea-95af-917550a0bc8f',panelIndex:'24',type:visualization,version:'6.4.2'),(embeddableConfig:(),gridData:(h:11,i:'25',w:31,x:0,y:107),id:'838d32f0-72fe-11ea-95af-917550a0bc8f',panelIndex:'25',type:visualization,version:'6.4.2'),(embeddableConfig:(),gridData:(h:21,i:'26',w:17,x:31,y:97),id:a7ed2e20-72fe-11ea-95af-917550a0bc8f,panelIndex:'26',type:visualization,version:'6.4.2'),(embeddableConfig:(),gridData:(h:10,i:'29',w:31,x:0,y:0),id:a0e60ef0-7324-11ea-95af-917550a0bc8f,panelIndex:'29',type:visualization,version:'6.4.2'),(embeddableConfig:(),gridData:(h:10,i:'30',w:17,x:31,y:0),id:cf110f00-7324-11ea-95af-917550a0bc8f,panelIndex:'30',type:visualization,version:'6.4.2'),(embeddableConfig:(),gridData:(h:10,i:'31',w:31,x:0,y:10),id:'0e7707e0-7a22-11ea-b987-ab21273de917',panelIndex:'31',type:visualization,version:'6.4.2'),(embeddableConfig:(),gridData:(h:19,i:'32',w:17,x:31,y:60),id:'82ba1a60-7a23-11ea-b27e-a53d919190b3',panelIndex:'32',type:visualization,version:'6.4.2'),(embeddableConfig:(),gridData:(h:23,i:'33',w:48,x:0,y:118),id:c372aca0-ba94-11ea-a8b6-e9141704cca0,panelIndex:'33',type:visualization,version:'6.8.0'),(embeddableConfig:(),gridData:(h:10,i:'34',w:31,x:0,y:20),id:'625e8670-c640-11ea-af3e-fb03f75ac9e6',panelIndex:'34',type:visualization,version:'6.8.0'),(embeddableConfig:(),gridData:(h:24,i:'35',w:48,x:0,y:141),id:'7ea8a0b0-d6b0-11ea-9d09-eb7b980d6b7e',panelIndex:'35',type:search,version:'6.8.0')),query:(language:lucene,query:'processName:*'),timeRestore:!f,title:das_Common_Process_detail,viewMode:view) | V7: =HYPERLINK(U7, "link") -> #VALUE!
U8: =Master!$R$2 &C8&Master!$R$3 -> https://rpa-dashboard.fastretailing.com/_plugin/kibana/app/kibana?security_tenant=global#/dashboard/77b46580-9bf7-11ea-a8b6-e9141704cca0?_g=(refreshInterval:(pause:!t,value:0),time:(from:'2020-10-04T15:00:00.000Z',mode:quick,to:'2020-10-11T14:59:59.999Z'))&_a=(description:'',filters:!(),fullScreenMode:!f,options:(darkTheme:!f,hidePanelTitles:!f,useMargins:!t),panels:!((embeddableConfig:(),gridData:(h:10,i:'3',w:17,x:31,y:20),id:e74898b0-61de-11ea-95af-917550a0bc8f,panelIndex:'3',type:visualization,version:'6.4.2'),(embeddableConfig:(),gridData:(h:10,i:'6',w:31,x:0,y:30),id:'8a0f3b00-6750-11ea-95af-917550a0bc8f',panelIndex:'6',type:visualization,version:'6.4.2'),(embeddableConfig:(),gridData:(h:10,i:'7',w:16,x:31,y:30),id:b10c4c00-6cf2-11ea-95af-917550a0bc8f,panelIndex:'7',type:visualization,version:'6.4.2'),(embeddableConfig:(),gridData:(h:10,i:'10',w:17,x:31,y:10),id:'8cae0c40-6cf7-11ea-95af-917550a0bc8f',panelIndex:'10',type:visualization,version:'6.4.2'),(embeddableConfig:(),gridData:(h:10,i:'12',w:16,x:31,y:40),id:'73b8e800-d601-11e9-a222-8b80233e6888',panelIndex:'12',type:visualization,version:'6.4.2'),(embeddableConfig:(),gridData:(h:10,i:'13',w:31,x:0,y:40),id:'58e36640-d601-11e9-a222-8b80233e6888',panelIndex:'13',type:visualization,version:'6.4.2'),(embeddableConfig:(),gridData:(h:10,i:'15',w:31,x:0,y:50),id:'578e0810-d604-11e9-a222-8b80233e6888',panelIndex:'15',type:visualization,version:'6.4.2'),(embeddableConfig:(),gridData:(h:10,i:'16',w:16,x:31,y:50),id:'88bdbca0-d604-11e9-a222-8b80233e6888',panelIndex:'16',type:visualization,version:'6.4.2'),(embeddableConfig:(),gridData:(h:9,i:'18',w:31,x:0,y:70),id:'0e4a0eb0-101a-11ea-95af-917550a0bc8f',panelIndex:'18',type:visualization,version:'6.4.2'),(embeddableConfig:(),gridData:(h:10,i:'19',w:31,x:0,y:60),id:fd252c00-1019-11ea-95af-917550a0bc8f,panelIndex:'19',type:visualization,version:'6.4.2'),(embeddableConfig:(vis:(colors:(BRO%E7%B5%82%E4%BA%86%E5%9B%9E%E6%95%B0:%23629E51,BRO%E9%96%8B%E5%A7%8B%E5%9B%9E%E6%95%B0:%23447EBC,'COM_TYPE:%22EXC%22+AND+COM_STATUS:%22START%22':%23629E51,EXCEL%E7%B5%82%E4%BA%86%E5%9B%9E%E6%95%B0:%23629E51,EXCEL%E9%96%8B%E5%A7%8B%E5%9B%9E%E6%95%B0:%2364B0C8),legendOpen:!t)),gridData:(h:8,i:'21',w:31,x:0,y:79),id:'42fb81e0-6f4f-11ea-95af-917550a0bc8f',panelIndex:'21',type:visualization,version:'6.4.2'),(embeddableConfig:(),gridData:(h:10,i:'22',w:31,x:0,y:87),id:'51f79120-6f4f-11ea-95af-917550a0bc8f',panelIndex:'22',type:visualization,version:'6.4.2'),(embeddableConfig:(),gridData:(h:18,i:'23',w:17,x:31,y:79),id:'6b8a80c0-6f4f-11ea-95af-917550a0bc8f',panelIndex:'23',type:visualization,version:'6.4.2'),(embeddableConfig:(),gridData:(h:10,i:'24',w:31,x:0,y:97),id:'707ecfc0-72fe-11ea-95af-917550a0bc8f',panelIndex:'24',type:visualization,version:'6.4.2'),(embeddableConfig:(),gridData:(h:11,i:'25',w:31,x:0,y:107),id:'838d32f0-72fe-11ea-95af-917550a0bc8f',panelIndex:'25',type:visualization,version:'6.4.2'),(embeddableConfig:(),gridData:(h:21,i:'26',w:17,x:31,y:97),id:a7ed2e20-72fe-11ea-95af-917550a0bc8f,panelIndex:'26',type:visualization,version:'6.4.2'),(embeddableConfig:(),gridData:(h:10,i:'29',w:31,x:0,y:0),id:a0e60ef0-7324-11ea-95af-917550a0bc8f,panelIndex:'29',type:visualization,version:'6.4.2'),(embeddableConfig:(),gridData:(h:10,i:'30',w:17,x:31,y:0),id:cf110f00-7324-11ea-95af-917550a0bc8f,panelIndex:'30',type:visualization,version:'6.4.2'),(embeddableConfig:(),gridData:(h:10,i:'31',w:31,x:0,y:10),id:'0e7707e0-7a22-11ea-b987-ab21273de917',panelIndex:'31',type:visualization,version:'6.4.2'),(embeddableConfig:(),gridData:(h:19,i:'32',w:17,x:31,y:60),id:'82ba1a60-7a23-11ea-b27e-a53d919190b3',panelIndex:'32',type:visualization,version:'6.4.2'),(embeddableConfig:(),gridData:(h:23,i:'33',w:48,x:0,y:118),id:c372aca0-ba94-11ea-a8b6-e9141704cca0,panelIndex:'33',type:visualization,version:'6.8.0'),(embeddableConfig:(),gridData:(h:10,i:'34',w:31,x:0,y:20),id:'625e8670-c640-11ea-af3e-fb03f75ac9e6',panelIndex:'34',type:visualization,version:'6.8.0'),(embeddableConfig:(),gridData:(h:24,i:'35',w:48,x:0,y:141),id:'7ea8a0b0-d6b0-11ea-9d09-eb7b980d6b7e',panelIndex:'35',type:search,version:'6.8.0')),query:(language:lucene,query:'processName:*'),timeRestore:!f,title:das_Common_Process_detail,viewMode:view) | V8: =HYPERLINK(U8, "link") -> #VALUE!
U9: =Master!$R$2 &C9&Master!$R$3 -> https://rpa-dashboard.fastretailing.com/_plugin/kibana/app/kibana?security_tenant=global#/dashboard/77b46580-9bf7-11ea-a8b6-e9141704cca0?_g=(refreshInterval:(pause:!t,value:0),time:(from:'2020-10-04T15:00:00.000Z',mode:quick,to:'2020-10-11T14:59:59.999Z'))&_a=(description:'',filters:!(),fullScreenMode:!f,options:(darkTheme:!f,hidePanelTitles:!f,useMargins:!t),panels:!((embeddableConfig:(),gridData:(h:10,i:'3',w:17,x:31,y:20),id:e74898b0-61de-11ea-95af-917550a0bc8f,panelIndex:'3',type:visualization,version:'6.4.2'),(embeddableConfig:(),gridData:(h:10,i:'6',w:31,x:0,y:30),id:'8a0f3b00-6750-11ea-95af-917550a0bc8f',panelIndex:'6',type:visualization,version:'6.4.2'),(embeddableConfig:(),gridData:(h:10,i:'7',w:16,x:31,y:30),id:b10c4c00-6cf2-11ea-95af-917550a0bc8f,panelIndex:'7',type:visualization,version:'6.4.2'),(embeddableConfig:(),gridData:(h:10,i:'10',w:17,x:31,y:10),id:'8cae0c40-6cf7-11ea-95af-917550a0bc8f',panelIndex:'10',type:visualization,version:'6.4.2'),(embeddableConfig:(),gridData:(h:10,i:'12',w:16,x:31,y:40),id:'73b8e800-d601-11e9-a222-8b80233e6888',panelIndex:'12',type:visualization,version:'6.4.2'),(embeddableConfig:(),gridData:(h:10,i:'13',w:31,x:0,y:40),id:'58e36640-d601-11e9-a222-8b80233e6888',panelIndex:'13',type:visualization,version:'6.4.2'),(embeddableConfig:(),gridData:(h:10,i:'15',w:31,x:0,y:50),id:'578e0810-d604-11e9-a222-8b80233e6888',panelIndex:'15',type:visualization,version:'6.4.2'),(embeddableConfig:(),gridData:(h:10,i:'16',w:16,x:31,y:50),id:'88bdbca0-d604-11e9-a222-8b80233e6888',panelIndex:'16',type:visualization,version:'6.4.2'),(embeddableConfig:(),gridData:(h:9,i:'18',w:31,x:0,y:70),id:'0e4a0eb0-101a-11ea-95af-917550a0bc8f',panelIndex:'18',type:visualization,version:'6.4.2'),(embeddableConfig:(),gridData:(h:10,i:'19',w:31,x:0,y:60),id:fd252c00-1019-11ea-95af-917550a0bc8f,panelIndex:'19',type:visualization,version:'6.4.2'),(embeddableConfig:(vis:(colors:(BRO%E7%B5%82%E4%BA%86%E5%9B%9E%E6%95%B0:%23629E51,BRO%E9%96%8B%E5%A7%8B%E5%9B%9E%E6%95%B0:%23447EBC,'COM_TYPE:%22EXC%22+AND+COM_STATUS:%22START%22':%23629E51,EXCEL%E7%B5%82%E4%BA%86%E5%9B%9E%E6%95%B0:%23629E51,EXCEL%E9%96%8B%E5%A7%8B%E5%9B%9E%E6%95%B0:%2364B0C8),legendOpen:!t)),gridData:(h:8,i:'21',w:31,x:0,y:79),id:'42fb81e0-6f4f-11ea-95af-917550a0bc8f',panelIndex:'21',type:visualization,version:'6.4.2'),(embeddableConfig:(),gridData:(h:10,i:'22',w:31,x:0,y:87),id:'51f79120-6f4f-11ea-95af-917550a0bc8f',panelIndex:'22',type:visualization,version:'6.4.2'),(embeddableConfig:(),gridData:(h:18,i:'23',w:17,x:31,y:79),id:'6b8a80c0-6f4f-11ea-95af-917550a0bc8f',panelIndex:'23',type:visualization,version:'6.4.2'),(embeddableConfig:(),gridData:(h:10,i:'24',w:31,x:0,y:97),id:'707ecfc0-72fe-11ea-95af-917550a0bc8f',panelIndex:'24',type:visualization,version:'6.4.2'),(embeddableConfig:(),gridData:(h:11,i:'25',w:31,x:0,y:107),id:'838d32f0-72fe-11ea-95af-917550a0bc8f',panelIndex:'25',type:visualization,version:'6.4.2'),(embeddableConfig:(),gridData:(h:21,i:'26',w:17,x:31,y:97),id:a7ed2e20-72fe-11ea-95af-917550a0bc8f,panelIndex:'26',type:visualization,version:'6.4.2'),(embeddableConfig:(),gridData:(h:10,i:'29',w:31,x:0,y:0),id:a0e60ef0-7324-11ea-95af-917550a0bc8f,panelIndex:'29',type:visualization,version:'6.4.2'),(embeddableConfig:(),gridData:(h:10,i:'30',w:17,x:31,y:0),id:cf110f00-7324-11ea-95af-917550a0bc8f,panelIndex:'30',type:visualization,version:'6.4.2'),(embeddableConfig:(),gridData:(h:10,i:'31',w:31,x:0,y:10),id:'0e7707e0-7a22-11ea-b987-ab21273de917',panelIndex:'31',type:visualization,version:'6.4.2'),(embeddableConfig:(),gridData:(h:19,i:'32',w:17,x:31,y:60),id:'82ba1a60-7a23-11ea-b27e-a53d919190b3',panelIndex:'32',type:visualization,version:'6.4.2'),(embeddableConfig:(),gridData:(h:23,i:'33',w:48,x:0,y:118),id:c372aca0-ba94-11ea-a8b6-e9141704cca0,panelIndex:'33',type:visualization,version:'6.8.0'),(embeddableConfig:(),gridData:(h:10,i:'34',w:31,x:0,y:20),id:'625e8670-c640-11ea-af3e-fb03f75ac9e6',panelIndex:'34',type:visualization,version:'6.8.0'),(embeddableConfig:(),gridData:(h:24,i:'35',w:48,x:0,y:141),id:'7ea8a0b0-d6b0-11ea-9d09-eb7b980d6b7e',panelIndex:'35',type:search,version:'6.8.0')),query:(language:lucene,query:'processName:*'),timeRestore:!f,title:das_Common_Process_detail,viewMode:view) | V9: =HYPERLINK(U9, "link") -> #VALUE!
U10: =Master!$R$2 &C10&Master!$R$3 -> https://rpa-dashboard.fastretailing.com/_plugin/kibana/app/kibana?security_tenant=global#/dashboard/77b46580-9bf7-11ea-a8b6-e9141704cca0?_g=(refreshInterval:(pause:!t,value:0),time:(from:'2020-10-04T15:00:00.000Z',mode:quick,to:'2020-10-11T14:59:59.999Z'))&_a=(description:'',filters:!(),fullScreenMode:!f,options:(darkTheme:!f,hidePanelTitles:!f,useMargins:!t),panels:!((embeddableConfig:(),gridData:(h:10,i:'3',w:17,x:31,y:20),id:e74898b0-61de-11ea-95af-917550a0bc8f,panelIndex:'3',type:visualization,version:'6.4.2'),(embeddableConfig:(),gridData:(h:10,i:'6',w:31,x:0,y:30),id:'8a0f3b00-6750-11ea-95af-917550a0bc8f',panelIndex:'6',type:visualization,version:'6.4.2'),(embeddableConfig:(),gridData:(h:10,i:'7',w:16,x:31,y:30),id:b10c4c00-6cf2-11ea-95af-917550a0bc8f,panelIndex:'7',type:visualization,version:'6.4.2'),(embeddableConfig:(),gridData:(h:10,i:'10',w:17,x:31,y:10),id:'8cae0c40-6cf7-11ea-95af-917550a0bc8f',panelIndex:'10',type:visualization,version:'6.4.2'),(embeddableConfig:(),gridData:(h:10,i:'12',w:16,x:31,y:40),id:'73b8e800-d601-11e9-a222-8b80233e6888',panelIndex:'12',type:visualization,version:'6.4.2'),(embeddableConfig:(),gridData:(h:10,i:'13',w:31,x:0,y:40),id:'58e36640-d601-11e9-a222-8b80233e6888',panelIndex:'13',type:visualization,version:'6.4.2'),(embeddableConfig:(),gridData:(h:10,i:'15',w:31,x:0,y:50),id:'578e0810-d604-11e9-a222-8b80233e6888',panelIndex:'15',type:visualization,version:'6.4.2'),(embeddableConfig:(),gridData:(h:10,i:'16',w:16,x:31,y:50),id:'88bdbca0-d604-11e9-a222-8b80233e6888',panelIndex:'16',type:visualization,version:'6.4.2'),(embeddableConfig:(),gridData:(h:9,i:'18',w:31,x:0,y:70),id:'0e4a0eb0-101a-11ea-95af-917550a0bc8f',panelIndex:'18',type:visualization,version:'6.4.2'),(embeddableConfig:(),gridData:(h:10,i:'19',w:31,x:0,y:60),id:fd252c00-1019-11ea-95af-917550a0bc8f,panelIndex:'19',type:visualization,version:'6.4.2'),(embeddableConfig:(vis:(colors:(BRO%E7%B5%82%E4%BA%86%E5%9B%9E%E6%95%B0:%23629E51,BRO%E9%96%8B%E5%A7%8B%E5%9B%9E%E6%95%B0:%23447EBC,'COM_TYPE:%22EXC%22+AND+COM_STATUS:%22START%22':%23629E51,EXCEL%E7%B5%82%E4%BA%86%E5%9B%9E%E6%95%B0:%23629E51,EXCEL%E9%96%8B%E5%A7%8B%E5%9B%9E%E6%95%B0:%2364B0C8),legendOpen:!t)),gridData:(h:8,i:'21',w:31,x:0,y:79),id:'42fb81e0-6f4f-11ea-95af-917550a0bc8f',panelIndex:'21',type:visualization,version:'6.4.2'),(embeddableConfig:(),gridData:(h:10,i:'22',w:31,x:0,y:87),id:'51f79120-6f4f-11ea-95af-917550a0bc8f',panelIndex:'22',type:visualization,version:'6.4.2'),(embeddableConfig:(),gridData:(h:18,i:'23',w:17,x:31,y:79),id:'6b8a80c0-6f4f-11ea-95af-917550a0bc8f',panelIndex:'23',type:visualization,version:'6.4.2'),(embeddableConfig:(),gridData:(h:10,i:'24',w:31,x:0,y:97),id:'707ecfc0-72fe-11ea-95af-917550a0bc8f',panelIndex:'24',type:visualization,version:'6.4.2'),(embeddableConfig:(),gridData:(h:11,i:'25',w:31,x:0,y:107),id:'838d32f0-72fe-11ea-95af-917550a0bc8f',panelIndex:'25',type:visualization,version:'6.4.2'),(embeddableConfig:(),gridData:(h:21,i:'26',w:17,x:31,y:97),id:a7ed2e20-72fe-11ea-95af-917550a0bc8f,panelIndex:'26',type:visualization,version:'6.4.2'),(embeddableConfig:(),gridData:(h:10,i:'29',w:31,x:0,y:0),id:a0e60ef0-7324-11ea-95af-917550a0bc8f,panelIndex:'29',type:visualization,version:'6.4.2'),(embeddableConfig:(),gridData:(h:10,i:'30',w:17,x:31,y:0),id:cf110f00-7324-11ea-95af-917550a0bc8f,panelIndex:'30',type:visualization,version:'6.4.2'),(embeddableConfig:(),gridData:(h:10,i:'31',w:31,x:0,y:10),id:'0e7707e0-7a22-11ea-b987-ab21273de917',panelIndex:'31',type:visualization,version:'6.4.2'),(embeddableConfig:(),gridData:(h:19,i:'32',w:17,x:31,y:60),id:'82ba1a60-7a23-11ea-b27e-a53d919190b3',panelIndex:'32',type:visualization,version:'6.4.2'),(embeddableConfig:(),gridData:(h:23,i:'33',w:48,x:0,y:118),id:c372aca0-ba94-11ea-a8b6-e9141704cca0,panelIndex:'33',type:visualization,version:'6.8.0'),(embeddableConfig:(),gridData:(h:10,i:'34',w:31,x:0,y:20),id:'625e8670-c640-11ea-af3e-fb03f75ac9e6',panelIndex:'34',type:visualization,version:'6.8.0'),(embeddableConfig:(),gridData:(h:24,i:'35',w:48,x:0,y:141),id:'7ea8a0b0-d6b0-11ea-9d09-eb7b980d6b7e',panelIndex:'35',type:search,version:'6.8.0')),query:(language:lucene,query:'processName:*'),timeRestore:!f,title:das_Common_Process_detail,viewMode:view) | V10: =HYPERLINK(U10, "link") -> #VALUE!
U11: =Master!$R$2 &C11&Master!$R$3 -> https://rpa-dashboard.fastretailing.com/_plugin/kibana/app/kibana?security_tenant=global#/dashboard/77b46580-9bf7-11ea-a8b6-e9141704cca0?_g=(refreshInterval:(pause:!t,value:0),time:(from:'2020-10-04T15:00:00.000Z',mode:quick,to:'2020-10-11T14:59:59.999Z'))&_a=(description:'',filters:!(),fullScreenMode:!f,options:(darkTheme:!f,hidePanelTitles:!f,useMargins:!t),panels:!((embeddableConfig:(),gridData:(h:10,i:'3',w:17,x:31,y:20),id:e74898b0-61de-11ea-95af-917550a0bc8f,panelIndex:'3',type:visualization,version:'6.4.2'),(embeddableConfig:(),gridData:(h:10,i:'6',w:31,x:0,y:30),id:'8a0f3b00-6750-11ea-95af-917550a0bc8f',panelIndex:'6',type:visualization,version:'6.4.2'),(embeddableConfig:(),gridData:(h:10,i:'7',w:16,x:31,y:30),id:b10c4c00-6cf2-11ea-95af-917550a0bc8f,panelIndex:'7',type:visualization,version:'6.4.2'),(embeddableConfig:(),gridData:(h:10,i:'10',w:17,x:31,y:10),id:'8cae0c40-6cf7-11ea-95af-917550a0bc8f',panelIndex:'10',type:visualization,version:'6.4.2'),(embeddableConfig:(),gridData:(h:10,i:'12',w:16,x:31,y:40),id:'73b8e800-d601-11e9-a222-8b80233e6888',panelIndex:'12',type:visualization,version:'6.4.2'),(embeddableConfig:(),gridData:(h:10,i:'13',w:31,x:0,y:40),id:'58e36640-d601-11e9-a222-8b80233e6888',panelIndex:'13',type:visualization,version:'6.4.2'),(embeddableConfig:(),gridData:(h:10,i:'15',w:31,x:0,y:50),id:'578e0810-d604-11e9-a222-8b80233e6888',panelIndex:'15',type:visualization,version:'6.4.2'),(embeddableConfig:(),gridData:(h:10,i:'16',w:16,x:31,y:50),id:'88bdbca0-d604-11e9-a222-8b80233e6888',panelIndex:'16',type:visualization,version:'6.4.2'),(embeddableConfig:(),gridData:(h:9,i:'18',w:31,x:0,y:70),id:'0e4a0eb0-101a-11ea-95af-917550a0bc8f',panelIndex:'18',type:visualization,version:'6.4.2'),(embeddableConfig:(),gridData:(h:10,i:'19',w:31,x:0,y:60),id:fd252c00-1019-11ea-95af-917550a0bc8f,panelIndex:'19',type:visualization,version:'6.4.2'),(embeddableConfig:(vis:(colors:(BRO%E7%B5%82%E4%BA%86%E5%9B%9E%E6%95%B0:%23629E51,BRO%E9%96%8B%E5%A7%8B%E5%9B%9E%E6%95%B0:%23447EBC,'COM_TYPE:%22EXC%22+AND+COM_STATUS:%22START%22':%23629E51,EXCEL%E7%B5%82%E4%BA%86%E5%9B%9E%E6%95%B0:%23629E51,EXCEL%E9%96%8B%E5%A7%8B%E5%9B%9E%E6%95%B0:%2364B0C8),legendOpen:!t)),gridData:(h:8,i:'21',w:31,x:0,y:79),id:'42fb81e0-6f4f-11ea-95af-917550a0bc8f',panelIndex:'21',type:visualization,version:'6.4.2'),(embeddableConfig:(),gridData:(h:10,i:'22',w:31,x:0,y:87),id:'51f79120-6f4f-11ea-95af-917550a0bc8f',panelIndex:'22',type:visualization,version:'6.4.2'),(embeddableConfig:(),gridData:(h:18,i:'23',w:17,x:31,y:79),id:'6b8a80c0-6f4f-11ea-95af-917550a0bc8f',panelIndex:'23',type:visualization,version:'6.4.2'),(embeddableConfig:(),gridData:(h:10,i:'24',w:31,x:0,y:97),id:'707ecfc0-72fe-11ea-95af-917550a0bc8f',panelIndex:'24',type:visualization,version:'6.4.2'),(embeddableConfig:(),gridData:(h:11,i:'25',w:31,x:0,y:107),id:'838d32f0-72fe-11ea-95af-917550a0bc8f',panelIndex:'25',type:visualization,version:'6.4.2'),(embeddableConfig:(),gridData:(h:21,i:'26',w:17,x:31,y:97),id:a7ed2e20-72fe-11ea-95af-917550a0bc8f,panelIndex:'26',type:visualization,version:'6.4.2'),(embeddableConfig:(),gridData:(h:10,i:'29',w:31,x:0,y:0),id:a0e60ef0-7324-11ea-95af-917550a0bc8f,panelIndex:'29',type:visualization,version:'6.4.2'),(embeddableConfig:(),gridData:(h:10,i:'30',w:17,x:31,y:0),id:cf110f00-7324-11ea-95af-917550a0bc8f,panelIndex:'30',type:visualization,version:'6.4.2'),(embeddableConfig:(),gridData:(h:10,i:'31',w:31,x:0,y:10),id:'0e7707e0-7a22-11ea-b987-ab21273de917',panelIndex:'31',type:visualization,version:'6.4.2'),(embeddableConfig:(),gridData:(h:19,i:'32',w:17,x:31,y:60),id:'82ba1a60-7a23-11ea-b27e-a53d919190b3',panelIndex:'32',type:visualization,version:'6.4.2'),(embeddableConfig:(),gridData:(h:23,i:'33',w:48,x:0,y:118),id:c372aca0-ba94-11ea-a8b6-e9141704cca0,panelIndex:'33',type:visualization,version:'6.8.0'),(embeddableConfig:(),gridData:(h:10,i:'34',w:31,x:0,y:20),id:'625e8670-c640-11ea-af3e-fb03f75ac9e6',panelIndex:'34',type:visualization,version:'6.8.0'),(embeddableConfig:(),gridData:(h:24,i:'35',w:48,x:0,y:141),id:'7ea8a0b0-d6b0-11ea-9d09-eb7b980d6b7e',panelIndex:'35',type:search,version:'6.8.0')),query:(language:lucene,query:'processName:*'),timeRestore:!f,title:das_Common_Process_detail,viewMode:view) | V11: =HYPERLINK(U11, "link") -> #VALUE!
U12: =Master!$R$2 &C12&Master!$R$3 -> https://rpa-dashboard.fastretailing.com/_plugin/kibana/app/kibana?security_tenant=global#/dashboard/77b46580-9bf7-11ea-a8b6-e9141704cca0?_g=(refreshInterval:(pause:!t,value:0),time:(from:'2020-10-04T15:00:00.000Z',mode:quick,to:'2020-10-11T14:59:59.999Z'))&_a=(description:'',filters:!(),fullScreenMode:!f,options:(darkTheme:!f,hidePanelTitles:!f,useMargins:!t),panels:!((embeddableConfig:(),gridData:(h:10,i:'3',w:17,x:31,y:20),id:e74898b0-61de-11ea-95af-917550a0bc8f,panelIndex:'3',type:visualization,version:'6.4.2'),(embeddableConfig:(),gridData:(h:10,i:'6',w:31,x:0,y:30),id:'8a0f3b00-6750-11ea-95af-917550a0bc8f',panelIndex:'6',type:visualization,version:'6.4.2'),(embeddableConfig:(),gridData:(h:10,i:'7',w:16,x:31,y:30),id:b10c4c00-6cf2-11ea-95af-917550a0bc8f,panelIndex:'7',type:visualization,version:'6.4.2'),(embeddableConfig:(),gridData:(h:10,i:'10',w:17,x:31,y:10),id:'8cae0c40-6cf7-11ea-95af-917550a0bc8f',panelIndex:'10',type:visualization,version:'6.4.2'),(embeddableConfig:(),gridData:(h:10,i:'12',w:16,x:31,y:40),id:'73b8e800-d601-11e9-a222-8b80233e6888',panelIndex:'12',type:visualization,version:'6.4.2'),(embeddableConfig:(),gridData:(h:10,i:'13',w:31,x:0,y:40),id:'58e36640-d601-11e9-a222-8b80233e6888',panelIndex:'13',type:visualization,version:'6.4.2'),(embeddableConfig:(),gridData:(h:10,i:'15',w:31,x:0,y:50),id:'578e0810-d604-11e9-a222-8b80233e6888',panelIndex:'15',type:visualization,version:'6.4.2'),(embeddableConfig:(),gridData:(h:10,i:'16',w:16,x:31,y:50),id:'88bdbca0-d604-11e9-a222-8b80233e6888',panelIndex:'16',type:visualization,version:'6.4.2'),(embeddableConfig:(),gridData:(h:9,i:'18',w:31,x:0,y:70),id:'0e4a0eb0-101a-11ea-95af-917550a0bc8f',panelIndex:'18',type:visualization,version:'6.4.2'),(embeddableConfig:(),gridData:(h:10,i:'19',w:31,x:0,y:60),id:fd252c00-1019-11ea-95af-917550a0bc8f,panelIndex:'19',type:visualization,version:'6.4.2'),(embeddableConfig:(vis:(colors:(BRO%E7%B5%82%E4%BA%86%E5%9B%9E%E6%95%B0:%23629E51,BRO%E9%96%8B%E5%A7%8B%E5%9B%9E%E6%95%B0:%23447EBC,'COM_TYPE:%22EXC%22+AND+COM_STATUS:%22START%22':%23629E51,EXCEL%E7%B5%82%E4%BA%86%E5%9B%9E%E6%95%B0:%23629E51,EXCEL%E9%96%8B%E5%A7%8B%E5%9B%9E%E6%95%B0:%2364B0C8),legendOpen:!t)),gridData:(h:8,i:'21',w:31,x:0,y:79),id:'42fb81e0-6f4f-11ea-95af-917550a0bc8f',panelIndex:'21',type:visualization,version:'6.4.2'),(embeddableConfig:(),gridData:(h:10,i:'22',w:31,x:0,y:87),id:'51f79120-6f4f-11ea-95af-917550a0bc8f',panelIndex:'22',type:visualization,version:'6.4.2'),(embeddableConfig:(),gridData:(h:18,i:'23',w:17,x:31,y:79),id:'6b8a80c0-6f4f-11ea-95af-917550a0bc8f',panelIndex:'23',type:visualization,version:'6.4.2'),(embeddableConfig:(),gridData:(h:10,i:'24',w:31,x:0,y:97),id:'707ecfc0-72fe-11ea-95af-917550a0bc8f',panelIndex:'24',type:visualization,version:'6.4.2'),(embeddableConfig:(),gridData:(h:11,i:'25',w:31,x:0,y:107),id:'838d32f0-72fe-11ea-95af-917550a0bc8f',panelIndex:'25',type:visualization,version:'6.4.2'),(embeddableConfig:(),gridData:(h:21,i:'26',w:17,x:31,y:97),id:a7ed2e20-72fe-11ea-95af-917550a0bc8f,panelIndex:'26',type:visualization,version:'6.4.2'),(embeddableConfig:(),gridData:(h:10,i:'29',w:31,x:0,y:0),id:a0e60ef0-7324-11ea-95af-917550a0bc8f,panelIndex:'29',type:visualization,version:'6.4.2'),(embeddableConfig:(),gridData:(h:10,i:'30',w:17,x:31,y:0),id:cf110f00-7324-11ea-95af-917550a0bc8f,panelIndex:'30',type:visualization,version:'6.4.2'),(embeddableConfig:(),gridData:(h:10,i:'31',w:31,x:0,y:10),id:'0e7707e0-7a22-11ea-b987-ab21273de917',panelIndex:'31',type:visualization,version:'6.4.2'),(embeddableConfig:(),gridData:(h:19,i:'32',w:17,x:31,y:60),id:'82ba1a60-7a23-11ea-b27e-a53d919190b3',panelIndex:'32',type:visualization,version:'6.4.2'),(embeddableConfig:(),gridData:(h:23,i:'33',w:48,x:0,y:118),id:c372aca0-ba94-11ea-a8b6-e9141704cca0,panelIndex:'33',type:visualization,version:'6.8.0'),(embeddableConfig:(),gridData:(h:10,i:'34',w:31,x:0,y:20),id:'625e8670-c640-11ea-af3e-fb03f75ac9e6',panelIndex:'34',type:visualization,version:'6.8.0'),(embeddableConfig:(),gridData:(h:24,i:'35',w:48,x:0,y:141),id:'7ea8a0b0-d6b0-11ea-9d09-eb7b980d6b7e',panelIndex:'35',type:search,version:'6.8.0')),query:(language:lucene,query:'processName:*'),timeRestore:!f,title:das_Common_Process_detail,viewMode:view) | V12: =HYPERLINK(U12, "link") -> #VALUE!
U13: =Master!$R$2 &C13&Master!$R$3 -> https://rpa-dashboard.fastretailing.com/_plugin/kibana/app/kibana?security_tenant=global#/dashboard/77b46580-9bf7-11ea-a8b6-e9141704cca0?_g=(refreshInterval:(pause:!t,value:0),time:(from:'2020-10-04T15:00:00.000Z',mode:quick,to:'2020-10-11T14:59:59.999Z'))&_a=(description:'',filters:!(),fullScreenMode:!f,options:(darkTheme:!f,hidePanelTitles:!f,useMargins:!t),panels:!((embeddableConfig:(),gridData:(h:10,i:'3',w:17,x:31,y:20),id:e74898b0-61de-11ea-95af-917550a0bc8f,panelIndex:'3',type:visualization,version:'6.4.2'),(embeddableConfig:(),gridData:(h:10,i:'6',w:31,x:0,y:30),id:'8a0f3b00-6750-11ea-95af-917550a0bc8f',panelIndex:'6',type:visualization,version:'6.4.2'),(embeddableConfig:(),gridData:(h:10,i:'7',w:16,x:31,y:30),id:b10c4c00-6cf2-11ea-95af-917550a0bc8f,panelIndex:'7',type:visualization,version:'6.4.2'),(embeddableConfig:(),gridData:(h:10,i:'10',w:17,x:31,y:10),id:'8cae0c40-6cf7-11ea-95af-917550a0bc8f',panelIndex:'10',type:visualization,version:'6.4.2'),(embeddableConfig:(),gridData:(h:10,i:'12',w:16,x:31,y:40),id:'73b8e800-d601-11e9-a222-8b80233e6888',panelIndex:'12',type:visualization,version:'6.4.2'),(embeddableConfig:(),gridData:(h:10,i:'13',w:31,x:0,y:40),id:'58e36640-d601-11e9-a222-8b80233e6888',panelIndex:'13',type:visualization,version:'6.4.2'),(embeddableConfig:(),gridData:(h:10,i:'15',w:31,x:0,y:50),id:'578e0810-d604-11e9-a222-8b80233e6888',panelIndex:'15',type:visualization,version:'6.4.2'),(embeddableConfig:(),gridData:(h:10,i:'16',w:16,x:31,y:50),id:'88bdbca0-d604-11e9-a222-8b80233e6888',panelIndex:'16',type:visualization,version:'6.4.2'),(embeddableConfig:(),gridData:(h:9,i:'18',w:31,x:0,y:70),id:'0e4a0eb0-101a-11ea-95af-917550a0bc8f',panelIndex:'18',type:visualization,version:'6.4.2'),(embeddableConfig:(),gridData:(h:10,i:'19',w:31,x:0,y:60),id:fd252c00-1019-11ea-95af-917550a0bc8f,panelIndex:'19',type:visualization,version:'6.4.2'),(embeddableConfig:(vis:(colors:(BRO%E7%B5%82%E4%BA%86%E5%9B%9E%E6%95%B0:%23629E51,BRO%E9%96%8B%E5%A7%8B%E5%9B%9E%E6%95%B0:%23447EBC,'COM_TYPE:%22EXC%22+AND+COM_STATUS:%22START%22':%23629E51,EXCEL%E7%B5%82%E4%BA%86%E5%9B%9E%E6%95%B0:%23629E51,EXCEL%E9%96%8B%E5%A7%8B%E5%9B%9E%E6%95%B0:%2364B0C8),legendOpen:!t)),gridData:(h:8,i:'21',w:31,x:0,y:79),id:'42fb81e0-6f4f-11ea-95af-917550a0bc8f',panelIndex:'21',type:visualization,version:'6.4.2'),(embeddableConfig:(),gridData:(h:10,i:'22',w:31,x:0,y:87),id:'51f79120-6f4f-11ea-95af-917550a0bc8f',panelIndex:'22',type:visualization,version:'6.4.2'),(embeddableConfig:(),gridData:(h:18,i:'23',w:17,x:31,y:79),id:'6b8a80c0-6f4f-11ea-95af-917550a0bc8f',panelIndex:'23',type:visualization,version:'6.4.2'),(embeddableConfig:(),gridData:(h:10,i:'24',w:31,x:0,y:97),id:'707ecfc0-72fe-11ea-95af-917550a0bc8f',panelIndex:'24',type:visualization,version:'6.4.2'),(embeddableConfig:(),gridData:(h:11,i:'25',w:31,x:0,y:107),id:'838d32f0-72fe-11ea-95af-917550a0bc8f',panelIndex:'25',type:visualization,version:'6.4.2'),(embeddableConfig:(),gridData:(h:21,i:'26',w:17,x:31,y:97),id:a7ed2e20-72fe-11ea-95af-917550a0bc8f,panelIndex:'26',type:visualization,version:'6.4.2'),(embeddableConfig:(),gridData:(h:10,i:'29',w:31,x:0,y:0),id:a0e60ef0-7324-11ea-95af-917550a0bc8f,panelIndex:'29',type:visualization,version:'6.4.2'),(embeddableConfig:(),gridData:(h:10,i:'30',w:17,x:31,y:0),id:cf110f00-7324-11ea-95af-917550a0bc8f,panelIndex:'30',type:visualization,version:'6.4.2'),(embeddableConfig:(),gridData:(h:10,i:'31',w:31,x:0,y:10),id:'0e7707e0-7a22-11ea-b987-ab21273de917',panelIndex:'31',type:visualization,version:'6.4.2'),(embeddableConfig:(),gridData:(h:19,i:'32',w:17,x:31,y:60),id:'82ba1a60-7a23-11ea-b27e-a53d919190b3',panelIndex:'32',type:visualization,version:'6.4.2'),(embeddableConfig:(),gridData:(h:23,i:'33',w:48,x:0,y:118),id:c372aca0-ba94-11ea-a8b6-e9141704cca0,panelIndex:'33',type:visualization,version:'6.8.0'),(embeddableConfig:(),gridData:(h:10,i:'34',w:31,x:0,y:20),id:'625e8670-c640-11ea-af3e-fb03f75ac9e6',panelIndex:'34',type:visualization,version:'6.8.0'),(embeddableConfig:(),gridData:(h:24,i:'35',w:48,x:0,y:141),id:'7ea8a0b0-d6b0-11ea-9d09-eb7b980d6b7e',panelIndex:'35',type:search,version:'6.8.0')),query:(language:lucene,query:'processName:*'),timeRestore:!f,title:das_Common_Process_detail,viewMode:view) | V13: =HYPERLINK(U13, "link") -> #VALUE!
... U51: =Master!$R$2 &C51&Master!$R$3 -> https://rpa-dashboard.fastretailing.com/_plugin/kibana/app/kibana?security_tenant=global#/dashboard/77b46580-9bf7-11ea-a8b6-e9141704cca0?_g=(refreshInterval:(pause:!t,value:0),time:(from:'2020-10-04T15:00:00.000Z',mode:quick,to:'2020-10-11T14:59:59.999Z'))&_a=(description:'',filters:!(),fullScreenMode:!f,options:(darkTheme:!f,hidePanelTitles:!f,useMargins:!t),panels:!((embeddableConfig:(),gridData:(h:10,i:'3',w:17,x:31,y:20),id:e74898b0-61de-11ea-95af-917550a0bc8f,panelIndex:'3',type:visualization,version:'6.4.2'),(embeddableConfig:(),gridData:(h:10,i:'6',w:31,x:0,y:30),id:'8a0f3b00-6750-11ea-95af-917550a0bc8f',panelIndex:'6',type:visualization,version:'6.4.2'),(embeddableConfig:(),gridData:(h:10,i:'7',w:16,x:31,y:30),id:b10c4c00-6cf2-11ea-95af-917550a0bc8f,panelIndex:'7',type:visualization,version:'6.4.2'),(embeddableConfig:(),gridData:(h:10,i:'10',w:17,x:31,y:10),id:'8cae0c40-6cf7-11ea-95af-917550a0bc8f',panelIndex:'10',type:visualization,version:'6.4.2'),(embeddableConfig:(),gridData:(h:10,i:'12',w:16,x:31,y:40),id:'73b8e800-d601-11e9-a222-8b80233e6888',panelIndex:'12',type:visualization,version:'6.4.2'),(embeddableConfig:(),gridData:(h:10,i:'13',w:31,x:0,y:40),id:'58e36640-d601-11e9-a222-8b80233e6888',panelIndex:'13',type:visualization,version:'6.4.2'),(embeddableConfig:(),gridData:(h:10,i:'15',w:31,x:0,y:50),id:'578e0810-d604-11e9-a222-8b80233e6888',panelIndex:'15',type:visualization,version:'6.4.2'),(embeddableConfig:(),gridData:(h:10,i:'16',w:16,x:31,y:50),id:'88bdbca0-d604-11e9-a222-8b80233e6888',panelIndex:'16',type:visualization,version:'6.4.2'),(embeddableConfig:(),gridData:(h:9,i:'18',w:31,x:0,y:70),id:'0e4a0eb0-101a-11ea-95af-917550a0bc8f',panelIndex:'18',type:visualization,version:'6.4.2'),(embeddableConfig:(),gridData:(h:10,i:'19',w:31,x:0,y:60),id:fd252c00-1019-11ea-95af-917550a0bc8f,panelIndex:'19',type:visualization,version:'6.4.2'),(embeddableConfig:(vis:(colors:(BRO%E7%B5%82%E4%BA%86%E5%9B%9E%E6%95%B0:%23629E51,BRO%E9%96%8B%E5%A7%8B%E5%9B%9E%E6%95%B0:%23447EBC,'COM_TYPE:%22EXC%22+AND+COM_STATUS:%22START%22':%23629E51,EXCEL%E7%B5%82%E4%BA%86%E5%9B%9E%E6%95%B0:%23629E51,EXCEL%E9%96%8B%E5%A7%8B%E5%9B%9E%E6%95%B0:%2364B0C8),legendOpen:!t)),gridData:(h:8,i:'21',w:31,x:0,y:79),id:'42fb81e0-6f4f-11ea-95af-917550a0bc8f',panelIndex:'21',type:visualization,version:'6.4.2'),(embeddableConfig:(),gridData:(h:10,i:'22',w:31,x:0,y:87),id:'51f79120-6f4f-11ea-95af-917550a0bc8f',panelIndex:'22',type:visualization,version:'6.4.2'),(embeddableConfig:(),gridData:(h:18,i:'23',w:17,x:31,y:79),id:'6b8a80c0-6f4f-11ea-95af-917550a0bc8f',panelIndex:'23',type:visualization,version:'6.4.2'),(embeddableConfig:(),gridData:(h:10,i:'24',w:31,x:0,y:97),id:'707ecfc0-72fe-11ea-95af-917550a0bc8f',panelIndex:'24',type:visualization,version:'6.4.2'),(embeddableConfig:(),gridData:(h:11,i:'25',w:31,x:0,y:107),id:'838d32f0-72fe-11ea-95af-917550a0bc8f',panelIndex:'25',type:visualization,version:'6.4.2'),(embeddableConfig:(),gridData:(h:21,i:'26',w:17,x:31,y:97),id:a7ed2e20-72fe-11ea-95af-917550a0bc8f,panelIndex:'26',type:visualization,version:'6.4.2'),(embeddableConfig:(),gridData:(h:10,i:'29',w:31,x:0,y:0),id:a0e60ef0-7324-11ea-95af-917550a0bc8f,panelIndex:'29',type:visualization,version:'6.4.2'),(embeddableConfig:(),gridData:(h:10,i:'30',w:17,x:31,y:0),id:cf110f00-7324-11ea-95af-917550a0bc8f,panelIndex:'30',type:visualization,version:'6.4.2'),(embeddableConfig:(),gridData:(h:10,i:'31',w:31,x:0,y:10),id:'0e7707e0-7a22-11ea-b987-ab21273de917',panelIndex:'31',type:visualization,version:'6.4.2'),(embeddableConfig:(),gridData:(h:19,i:'32',w:17,x:31,y:60),id:'82ba1a60-7a23-11ea-b27e-a53d919190b3',panelIndex:'32',type:visualization,version:'6.4.2'),(embeddableConfig:(),gridData:(h:23,i:'33',w:48,x:0,y:118),id:c372aca0-ba94-11ea-a8b6-e9141704cca0,panelIndex:'33',type:visualization,version:'6.8.0'),(embeddableConfig:(),gridData:(h:10,i:'34',w:31,x:0,y:20),id:'625e8670-c640-11ea-af3e-fb03f75ac9e6',panelIndex:'34',type:visualization,version:'6.8.0'),(embeddableConfig:(),gridData:(h:24,i:'35',w:48,x:0,y:141),id:'7ea8a0b0-d6b0-11ea-9d09-eb7b980d6b7e',panelIndex:'35',type:search,version:'6.8.0')),query:(language:lucene,query:'processName:*'),timeRestore:!f,title:das_Common_Process_detail,viewMode:view) | V51: =HYPERLINK(U51, "link") -> #VALUE!

Sheet Master
A1: 利用されていない原因 / Cause | B1: 原因カテゴリー | H1: 対策 | I1: 対策（JP) | J1: 対策（EN) | M1: 稼働率が低い原因 / Cause | N1: 対策 / Action | O1: カテゴリー
